Workbook
Name Slicer_Representative: #N/A

Sheet Assets
E2: Rep ID | F2: Rep Image
E3: R01
E4: R02
E5: R03
E6: R04
E7: R05
G13: =G3 -> 0

Sheet Data
B1: Call Centre Data
B3: Call number | C3: Customer ID | D3: Duration | E3: Representative | F3: Date of Call | G3: Purchase Amount | H3: Satisfaction Rating | I3: FY | J3: Day of week | K3: Duration Bucket | L3: Rating rounded | Q3: Customer ID | R3: Gedner | S3: Age | T3: City
B4: Call_7271 | C4: C0003 | D4: 116 | E4: R05 | F4: 44927 | G4: 128 | H4: 4.9 | I4: =IF(MONTH(calls[[#This Row],[Date of Call]])<=6, YEAR(calls[[#This Row],[Date of Call]]), YEAR(calls[[#This Row],[Date of Call]])+1) -> 2023 | J4: =TEXT(calls[[#This Row],[Date of Call]],"DDDD") -> Sunday | K4: {=_xlfn.IFS(calls[[#This Row],[Duration]]<=10,"Under 10 mins", calls[[#This Row],[Duration]]<=30, "10 to 30 mins", calls[[#This Row],[Duration]]<=60, "30 to 60 mins", calls[[#This Row],[Duration]]<=120, "1 to 2 hours", TRUE, "More than 2 hours")} -> 1 to 2 hours | L4: =ROUND(calls[[#This Row],[Satisfaction Rating]],0) -> 5 | Q4: C0001 | R4: Male | S4: 41 | T4: Columbus
B5: Call_7272 | C5: C0004 | D5: 119 | E5: R05 | F5: 44927 | G5: 135 | H5: 2.9 | I5: =IF(MONTH(calls[[#This Row],[Date of Call]])<=6, YEAR(calls[[#This Row],[Date of Call]]), YEAR(calls[[#This Row],[Date of Call]])+1) -> 2023 | J5: =TEXT(calls[[#This Row],[Date of Call]],"DDDD") -> Sunday | K5: {=_xlfn.IFS(calls[[#This Row],[Duration]]<=10,"Under 10 mins", calls[[#This Row],[Duration]]<=30, "10 to 30 mins", calls[[#This Row],[Duration]]<=60, "30 to 60 mins", calls[[#This Row],[Duration]]<=120, "1 to 2 hours", TRUE, "More than 2 hours")} -> 1 to 2 hours | L5: =ROUND(calls[[#This Row],[Satisfaction Rating]],0) -> 3 | Q5: C0002 | R5: Male | S5: 31 | T5: Cleveland
B6: Call_7273 | C6: C0005 | D6: 68 | E6: R02 | F6: 44927 | G6: 66 | H6: 4.7 | I6: =IF(MONTH(calls[[#This Row],[Date of Call]])<=6, YEAR(calls[[#This Row],[Date of Call]]), YEAR(calls[[#This Row],[Date of Call]])+1) -> 2023 | J6: =TEXT(calls[[#This Row],[Date of Call]],"DDDD") -> Sunday | K6: {=_xlfn.IFS(calls[[#This Row],[Duration]]<=10,"Under 10 mins", calls[[#This Row],[Duration]]<=30, "10 to 30 mins", calls[[#This Row],[Duration]]<=60, "30 to 60 mins", calls[[#This Row],[Duration]]<=120, "1 to 2 hours", TRUE, "More than 2 hours")} -> 1 to 2 hours | L6: =ROUND(calls[[#This Row],[Satisfaction Rating]],0) -> 5 | Q6: C0003 | R6: Male | S6: 26 | T6: Cincinnati
B7: Call_7274 | C7: C0014 | D7: 119 | E7: R02 | F7: 44927 | G7: 22 | H7: 2.9 | I7: =IF(MONTH(calls[[#This Row],[Date of Call]])<=6, YEAR(calls[[#This Row],[Date of Call]]), YEAR(calls[[#This Row],[Date of Call]])+1) -> 2023 | J7: =TEXT(calls[[#This Row],[Date of Call]],"DDDD") -> Sunday | K7: {=_xlfn.IFS(calls[[#This Row],[Duration]]<=10,"Under 10 mins", calls[[#This Row],[Duration]]<=30, "10 to 30 mins", calls[[#This Row],[Duration]]<=60, "30 to 60 mins", calls[[#This Row],[Duration]]<=120, "1 to 2 hours", TRUE, "More than 2 hours")} -> 1 to 2 hours | L7: =ROUND(calls[[#This Row],[Satisfaction Rating]],0) -> 3 | Q7: C0004 | R7: Male | S7: 36 | T7: Cincinnati
B8: Call_7275 | C8: C0011 | D8: 128 | E8: R01 | F8: 44928 | G8: 31 | H8: 2.8 | I8: =IF(MONTH(calls[[#This Row],[Date of Call]])<=6, YEAR(calls[[#This Row],[Date of Call]]), YEAR(calls[[#This Row],[Date of Call]])+1) -> 2023 | J8: =TEXT(calls[[#This Row],[Date of Call]],"DDDD") -> Monday | K8: {=_xlfn.IFS(calls[[#This Row],[Duration]]<=10,"Under 10 mins", calls[[#This Row],[Duration]]<=30, "10 to 30 mins", calls[[#This Row],[Duration]]<=60, "30 to 60 mins", calls[[#This Row],[Duration]]<=120, "1 to 2 hours", TRUE, "More than 2 hours")} -> More than 2 hours | L8: =ROUND(calls[[#This Row],[Satisfaction Rating]],0) -> 3 | Q8: C0005 | R8: Male | S8: 37 | T8: Columbus
B9: Call_7276 | C9: C0011 | D9: 49 | E9: R02 | F9: 44929 | G9: 135 | H9: 4.8 | I9: =IF(MONTH(calls[[#This Row],[Date of Call]])<=6, YEAR(calls[[#This Row],[Date of Call]]), YEAR(calls[[#This Row],[Date of Call]])+1) -> 2023 | J9: =TEXT(calls[[#This Row],[Date of Call]],"DDDD") -> Tuesday | K9: {=_xlfn.IFS(calls[[#This Row],[Duration]]<=10,"Under 10 mins", calls[[#This Row],[Duration]]<=30, "10 to 30 mins", calls[[#This Row],[Duration]]<=60, "30 to 60 mins", calls[[#This Row],[Duration]]<=120, "1 to 2 hours", TRUE, "More than 2 hours")} -> 30 to 60 mins | L9: =ROUND(calls[[#This Row],[Satisfaction Rating]],0) -> 5 | Q9: C0006 | R9: Male | S9: 23 | T9: Columbus
B10: Call_7277 | C10: C0007 | D10: 84 | E10: R05 | F10: 44929 | G10: 60 | H10: 4.7 | I10: =IF(MONTH(calls[[#This Row],[Date of Call]])<=6, YEAR(calls[[#This Row],[Date of Call]]), YEAR(calls[[#This Row],[Date of Call]])+1) -> 2023 | J10: =TEXT(calls[[#This Row],[Date of Call]],"DDDD") -> Tuesday | K10: {=_xlfn.IFS(calls[[#This Row],[Duration]]<=10,"Under 10 mins", calls[[#This Row],[Duration]]<=30, "10 to 30 mins", calls[[#This Row],[Duration]]<=60, "30 to 60 mins", calls[[#This Row],[Duration]]<=120, "1 to 2 hours", TRUE, "More than 2 hours")} -> 1 to 2 hours | L10: =ROUND(calls[[#This Row],[Satisfaction Rating]],0) -> 5 | Q10: C0007 | R10: Female | S10: 22 | T10: Cleveland
B11: Call_7278 | C11: C0003 | D11: 103 | E11: R04 | F11: 44929 | G11: 148 | H11: 4.4 | I11: =IF(MONTH(calls[[#This Row],[Date of Call]])<=6, YEAR(calls[[#This Row],[Date of Call]]), YEAR(calls[[#This Row],[Date of Call]])+1) -> 2023 | J11: =TEXT(calls[[#This Row],[Date of Call]],"DDDD") -> Tuesday | K11: {=_xlfn.IFS(calls[[#This Row],[Duration]]<=10,"Under 10 mins", calls[[#This Row],[Duration]]<=30, "10 to 30 mins", calls[[#This Row],[Duration]]<=60, "30 to 60 mins", calls[[#This Row],[Duration]]<=120, "1 to 2 hours", TRUE, "More than 2 hours")} -> 1 to 2 hours | L11: =ROUND(calls[[#This Row],[Satisfaction Rating]],0) -> 4 | Q11: C0008 | R11: Female | S11: 42 | T11: Cleveland
B12: Call_7279 | C12: C0005 | D12: 31 | E12: R02 | F12: 44929 | G12: 135 | H12: 3.6 | I12: =IF(MONTH(calls[[#This Row],[Date of Call]])<=6, YEAR(calls[[#This Row],[Date of Call]]), YEAR(calls[[#This Row],[Date of Call]])+1) -> 2023 | J12: =TEXT(calls[[#This Row],[Date of Call]],"DDDD") -> Tuesday | K12: {=_xlfn.IFS(calls[[#This Row],[Duration]]<=10,"Under 10 mins", calls[[#This Row],[Duration]]<=30, "10 to 30 mins", calls[[#This Row],[Duration]]<=60, "30 to 60 mins", calls[[#This Row],[Duration]]<=120, "1 to 2 hours", TRUE, "More than 2 hours")} -> 30 to 60 mins | L12: =ROUND(calls[[#This Row],[Satisfaction Rating]],0) -> 4 | Q12: C0009 | R12: Female | S12: 25 | T12: Columbus
B13: Call_7280 | C13: C0010 | D13: 44 | E13: R03 | F13: 44929 | G13: 105 | H13: 2.9 | I13: =IF(MONTH(calls[[#This Row],[Date of Call]])<=6, YEAR(calls[[#This Row],[Date of Call]]), YEAR(calls[[#This Row],[Date of Call]])+1) -> 2023 | J13: =TEXT(calls[[#This Row],[Date of Call]],"DDDD") -> Tuesday | K13: {=_xlfn.IFS(calls[[#This Row],[Duration]]<=10,"Under 10 mins", calls[[#This Row],[Duration]]<=30, "10 to 30 mins", calls[[#This Row],[Duration]]<=60, "30 to 60 mins", calls[[#This Row],[Duration]]<=120, "1 to 2 hours", TRUE, "More than 2 hours")} -> 30 to 60 mins | L13: =ROUND(calls[[#This Row],[Satisfaction Rating]],0) -> 3 | Q13: C0010 | R13: Female | S13: 30 | T13: Cleveland
B14: Call_7281 | C14: C0011 | D14: 102 | E14: R02 | F14: 44929 | G14: 69 | H14: 4.9 | I14: =IF(MONTH(calls[[#This Row],[Date of Call]])<=6, YEAR(calls[[#This Row],[Date of Call]]), YEAR(calls[[#This Row],[Date of Call]])+1) -> 2023 | J14: =TEXT(calls[[#This Row],[Date of Call]],"DDDD") -> Tuesday | K14: {=_xlfn.IFS(calls[[#This Row],[Duration]]<=10,"Under 10 mins", calls[[#This Row],[Duration]]<=30, "10 to 30 mins", calls[[#This Row],[Duration]]<=60, "30 to 60 mins", calls[[#This Row],[Duration]]<=120, "1 to 2 hours", TRUE, "More than 2 hours")} -> 1 to 2 hours | L14: =ROUND(calls[[#This Row],[Satisfaction Rating]],0) -> 5 | Q14: C0011 | R14: Female | S14: 30 | T14: Cincinnati
B15: Call_7282 | C15: C0013 | D15: 135 | E15: R05 | F15: 44929 | G15: 46 | H15: 3.4 | I15: =IF(MONTH(calls[[#This Row],[Date of Call]])<=6, YEAR(calls[[#This Row],[Date of Call]]), YEAR(calls[[#This Row],[Date of Call]])+1) -> 2023 | J15: =TEXT(calls[[#This Row],[Date of Call]],"DDDD") -> Tuesday | K15: {=_xlfn.IFS(calls[[#This Row],[Duration]]<=10,"Under 10 mins", calls[[#This Row],[Duration]]<=30, "10 to 30 mins", calls[[#This Row],[Duration]]<=60, "30 to 60 mins", calls[[#This Row],[Duration]]<=120, "1 to 2 hours", TRUE, "More than 2 hours")} -> More than 2 hours | L15: =ROUND(calls[[#This Row],[Satisfaction Rating]],0) -> 3 | Q15: C0012 | R15: Female | S15: 28 | T15: Cincinnati
... B18: Call_7285 | C18: C0013 | D18: 48 | E18: R01 | F18: 44930 | G18: 68 | H18: 4.9 | I18: =IF(MONTH(calls[[#This Row],[Date of Call]])<=6, YEAR(calls[[#This Row],[Date of Call]]), YEAR(calls[[#This Row],[Date of Call]])+1) -> 2023 | J18: =TEXT(calls[[#This Row],[Date of Call]],"DDDD") -> Wednesday | K18: {=_xlfn.IFS(calls[[#This Row],[Duration]]<=10,"Under 10 mins", calls[[#This Row],[Duration]]<=30, "10 to 30 mins", calls[[#This Row],[Duration]]<=60, "30 to 60 mins", calls[[#This Row],[Duration]]<=120, "1 to 2 hours", TRUE, "More than 2 hours")} -> 30 to 60 mins | L18: =ROUND(calls[[#This Row],[Satisfaction Rating]],0) -> 5 | Q18: C0015 | R18: Female | S18: 43 | T18: Cleveland
B19: Call_7286 | C19: C0010 | D19: 176 | E19: R05 | F19: 44931 | G19: 24 | H19: 4.8 | I19: =IF(MONTH(calls[[#This Row],[Date of Call]])<=6, YEAR(calls[[#This Row],[Date of Call]]), YEAR(calls[[#This Row],[Date of Call]])+1) -> 2023 | J19: =TEXT(calls[[#This Row],[Date of Call]],"DDDD") -> Thursday | K19: {=_xlfn.IFS(calls[[#This Row],[Duration]]<=10,"Under 10 mins", calls[[#This Row],[Duration]]<=30, "10 to 30 mins", calls[[#This Row],[Duration]]<=60, "30 to 60 mins", calls[[#This Row],[Duration]]<=120, "1 to 2 hours", TRUE, "More than 2 hours")} -> More than 2 hours | L19: =ROUND(calls[[#This Row],[Satisfaction Rating]],0) -> 5
B20: Call_7287 | C20: C0010 | D20: 99 | E20: R01 | F20: 44931 | G20: 195 | H20: 3.9 | I20: =IF(MONTH(calls[[#This Row],[Date of Call]])<=6, YEAR(calls[[#This Row],[Date of Call]]), YEAR(calls[[#This Row],[Date of Call]])+1) -> 2023 | J20: =TEXT(calls[[#This Row],[Date of Call]],"DDDD") -> Thursday | K20: {=_xlfn.IFS(calls[[#This Row],[Duration]]<=10,"Under 10 mins", calls[[#This Row],[Duration]]<=30, "10 to 30 mins", calls[[#This Row],[Duration]]<=60, "30 to 60 mins", calls[[#This Row],[Duration]]<=120, "1 to 2 hours", TRUE, "More than 2 hours")} -> 1 to 2 hours | L20: =ROUND(calls[[#This Row],[Satisfaction Rating]],0) -> 4
B21: Call_7288 | C21: C0009 | D21: 28 | E21: R03 | F21: 44931 | G21: 28 | H21: 3.8 | I21: =IF(MONTH(calls[[#This Row],[Date of Call]])<=6, YEAR(calls[[#This Row],[Date of Call]]), YEAR(calls[[#This Row],[Date of Call]])+1) -> 2023 | J21: =TEXT(calls[[#This Row],[Date of Call]],"DDDD") -> Thursday | K21: {=_xlfn.IFS(calls[[#This Row],[Duration]]<=10,"Under 10 mins", calls[[#This Row],[Duration]]<=30, "10 to 30 mins", calls[[#This Row],[Duration]]<=60, "30 to 60 mins", calls[[#This Row],[Duration]]<=120, "1 to 2 hours", TRUE, "More than 2 hours")} -> 10 to 30 mins | L21: =ROUND(calls[[#This Row],[Satisfaction Rating]],0) -> 4
B22: Call_7289 | C22: C0007 | D22: 54 | E22: R02 | F22: 44931 | G22: 170 | H22: 4.3 | I22: =IF(MONTH(calls[[#This Row],[Date of Call]])<=6, YEAR(calls[[#This Row],[Date of Call]]), YEAR(calls[[#This Row],[Date of Call]])+1) -> 2023 | J22: =TEXT(calls[[#This Row],[Date of Call]],"DDDD") -> Thursday | K22: {=_xlfn.IFS(calls[[#This Row],[Duration]]<=10,"Under 10 mins", calls[[#This Row],[Duration]]<=30, "10 to 30 mins", calls[[#This Row],[Duration]]<=60, "30 to 60 mins", calls[[#This Row],[Duration]]<=120, "1 to 2 hours", TRUE, "More than 2 hours")} -> 30 to 60 mins | L22: =ROUND(calls[[#This Row],[Satisfaction Rating]],0) -> 4
B23: Call_7290 | C23: C0006 | D23: 48 | E23: R05 | F23: 44932 | G23: 30 | H23: 4.4 | I23: =IF(MONTH(calls[[#This Row],[Date of Call]])<=6, YEAR(calls[[#This Row],[Date of Call]]), YEAR(calls[[#This Row],[Date of Call]])+1) -> 2023 | J23: =TEXT(calls[[#This Row],[Date of Call]],"DDDD") -> Friday | K23: {=_xlfn.IFS(calls[[#This Row],[Duration]]<=10,"Under 10 mins", calls[[#This Row],[Duration]]<=30, "10 to 30 mins", calls[[#This Row],[Duration]]<=60, "30 to 60 mins", calls[[#This Row],[Duration]]<=120, "1 to 2 hours", TRUE, "More than 2 hours")} -> 30 to 60 mins | L23: =ROUND(calls[[#This Row],[Satisfaction Rating]],0) -> 4
B24: Call_7291 | C24: C0004 | D24: 128 | E24: R05 | F24: 44932 | G24: 72 | H24: 5 | I24: =IF(MONTH(calls[[#This Row],[Date of Call]])<=6, YEAR(calls[[#This Row],[Date of Call]]), YEAR(calls[[#This Row],[Date of Call]])+1) -> 2023 | J24: =TEXT(calls[[#This Row],[Date of Call]],"DDDD") -> Friday | K24: {=_xlfn.IFS(calls[[#This Row],[Duration]]<=10,"Under 10 mins", calls[[#This Row],[Duration]]<=30, "10 to 30 mins", calls[[#This Row],[Duration]]<=60, "30 to 60 mins", calls[[#This Row],[Duration]]<=120, "1 to 2 hours", TRUE, "More than 2 hours")} -> More than 2 hours | L24: =ROUND(calls[[#This Row],[Satisfaction Rating]],0) -> 5
B25: Call_7292 | C25: C0004 | D25: 38 | E25: R04 | F25: 44933 | G25: 92 | H25: 4.9 | I25: =IF(MONTH(calls[[#This Row],[Date of Call]])<=6, YEAR(calls[[#This Row],[Date of Call]]), YEAR(calls[[#This Row],[Date of Call]])+1) -> 2023 | J25: =TEXT(calls[[#This Row],[Date of Call]],"DDDD") -> Saturday | K25: {=_xlfn.IFS(calls[[#This Row],[Duration]]<=10,"Under 10 mins", calls[[#This Row],[Duration]]<=30, "10 to 30 mins", calls[[#This Row],[Duration]]<=60, "30 to 60 mins", calls[[#This Row],[Duration]]<=120, "1 to 2 hours", TRUE, "More than 2 hours")} -> 30 to 60 mins | L25: =ROUND(calls[[#This Row],[Satisfaction Rating]],0) -> 5
B26: Call_7293 | C26: C0003 | D26: 67 | E26: R04 | F26: 44934 | G26: 165 | H26: 4.5 | I26: =IF(MONTH(calls[[#This Row],[Date of Call]])<=6, YEAR(calls[[#This Row],[Date of Call]]), YEAR(calls[[#This Row],[Date of Call]])+1) -> 2023 | J26: =TEXT(calls[[#This Row],[Date of Call]],"DDDD") -> Sunday | K26: {=_xlfn.IFS(calls[[#This Row],[Duration]]<=10,"Under 10 mins", calls[[#This Row],[Duration]]<=30, "10 to 30 mins", calls[[#This Row],[Duration]]<=60, "30 to 60 mins", calls[[#This Row],[Duration]]<=120, "1 to 2 hours", TRUE, "More than 2 hours")} -> 1 to 2 hours | L26: =ROUND(calls[[#This Row],[Satisfaction Rating]],0) -> 5
B27: Call_7294 | C27: C0015 | D27: 58 | E27: R02 | F27: 44934 | G27: 140 | H27: 2.1 | I27: =IF(MONTH(calls[[#This Row],[Date of Call]])<=6, YEAR(calls[[#This Row],[Date of Call]]), YEAR(calls[[#This Row],[Date of Call]])+1) -> 2023 | J27: =TEXT(calls[[#This Row],[Date of Call]],"DDDD") -> Sunday | K27: {=_xlfn.IFS(calls[[#This Row],[Duration]]<=10,"Under 10 mins", calls[[#This Row],[Duration]]<=30, "10 to 30 mins", calls[[#This Row],[Duration]]<=60, "30 to 60 mins", calls[[#This Row],[Duration]]<=120, "1 to 2 hours", TRUE, "More than 2 hours")} -> 30 to 60 mins | L27: =ROUND(calls[[#This Row],[Satisfaction Rating]],0) -> 2
B28: Call_7295 | C28: C0010 | D28: 54 | E28: R01 | F28: 44934 | G28: 111 | H28: 3.3 | I28: =IF(MONTH(calls[[#This Row],[Date of Call]])<=6, YEAR(calls[[#This Row],[Date of Call]]), YEAR(calls[[#This Row],[Date of Call]])+1) -> 2023 | J28: =TEXT(calls[[#This Row],[Date of Call]],"DDDD") -> Sunday | K28: {=_xlfn.IFS(calls[[#This Row],[Duration]]<=10,"Under 10 mins", calls[[#This Row],[Duration]]<=30, "10 to 30 mins", calls[[#This Row],[Duration]]<=60, "30 to 60 mins", calls[[#This Row],[Duration]]<=120, "1 to 2 hours", TRUE, "More than 2 hours")} -> 30 to 60 mins | L28: =ROUND(calls[[#This Row],[Satisfaction Rating]],0) -> 3
B29: Call_7296 | C29: C0012 | D29: 28 | E29: R05 | F29: 44935 | G29: 63 | H29: 4.1 | I29: =IF(MONTH(calls[[#This Row],[Date of Call]])<=6, YEAR(calls[[#This Row],[Date of Call]]), YEAR(calls[[#This Row],[Date of Call]])+1) -> 2023 | J29: =TEXT(calls[[#This Row],[Date of Call]],"DDDD") -> Monday | K29: {=_xlfn.IFS(calls[[#This Row],[Duration]]<=10,"Under 10 mins", calls[[#This Row],[Duration]]<=30, "10 to 30 mins", calls[[#This Row],[Duration]]<=60, "30 to 60 mins", calls[[#This Row],[Duration]]<=120, "1 to 2 hours", TRUE, "More than 2 hours")} -> 10 to 30 mins | L29: =ROUND(calls[[#This Row],[Satisfaction Rating]],0) -> 4
B30: Call_7297 | C30: C0002 | D30: 73 | E30: R05 | F30: 44935 | G30: 80 | H30: 4.2 | I30: =IF(MONTH(calls[[#This Row],[Date of Call]])<=6, YEAR(calls[[#This Row],[Date of Call]]), YEAR(calls[[#This Row],[Date of Call]])+1) -> 2023 | J30: =TEXT(calls[[#This Row],[Date of Call]],"DDDD") -> Monday | K30: {=_xlfn.IFS(calls[[#This Row],[Duration]]<=10,"Under 10 mins", calls[[#This Row],[Duration]]<=30, "10 to 30 mins", calls[[#This Row],[Duration]]<=60, "30 to 60 mins", calls[[#This Row],[Duration]]<=120, "1 to 2 hours", TRUE, "More than 2 hours")} -> 1 to 2 hours | L30: =ROUND(calls[[#This Row],[Satisfaction Rating]],0) -> 4
... B1003: Call_8270 | C1003: C0009 | D1003: 114 | E1003: R01 | F1003: 45291 | G1003: 40 | H1003: 3.9 | I1003: =IF(MONTH(calls[[#This Row],[Date of Call]])<=6, YEAR(calls[[#This Row],[Date of Call]]), YEAR(calls[[#This Row],[Date of Call]])+1) -> 2024 | J1003: =TEXT(calls[[#This Row],[Date of Call]],"DDDD") -> Sunday | K1003: {=_xlfn.IFS(calls[[#This Row],[Duration]]<=10,"Under 10 mins", calls[[#This Row],[Duration]]<=30, "10 to 30 mins", calls[[#This Row],[Duration]]<=60, "30 to 60 mins", calls[[#This Row],[Duration]]<=120, "1 to 2 hours", TRUE, "More than 2 hours")} -> 1 to 2 hours | L1003: =ROUND(calls[[#This Row],[Satisfaction Rating]],0) -> 4

Sheet Sheet4
A1: Data returned for 5 star calls, All (First 1000 rows).
A3: calls[Call number] | B3: calls[Customer ID] | C3: calls[Duration] | D3: calls[Representative] | E3: calls[Date of Call] | F3: calls[Purchase Amount] | G3: calls[Satisfaction Rating] | H3: calls[FY] | I3: calls[Day of week] | J3: calls[Duration Bucket] | K3: calls[Rating rounded] | L3: calls[Date of Call (Month)] | M3: calls[Date of Call (Month Index)]
A4: Call_7271 | B4: C0003 | C4: 116 | D4: R05 | E4: 44927 | F4: 128 | G4: 4.9 | H4: 2023 | I4: Sunday | J4: 1 to 2 hours | K4: 5 | L4: Jan | M4: 1
A5: Call_7272 | B5: C0004 | C5: 119 | D5: R05 | E5: 44927 | F5: 135 | G5: 2.9 | H5: 2023 | I5: Sunday | J5: 1 to 2 hours | K5: 3 | L5: Jan | M5: 1
A6: Call_7273 | B6: C0005 | C6: 68 | D6: R02 | E6: 44927 | F6: 66 | G6: 4.7 | H6: 2023 | I6: Sunday | J6: 1 to 2 hours | K6: 5 | L6: Jan | M6: 1
A7: Call_7274 | B7: C0014 | C7: 119 | D7: R02 | E7: 44927 | F7: 22 | G7: 2.9 | H7: 2023 | I7: Sunday | J7: 1 to 2 hours | K7: 3 | L7: Jan | M7: 1
A8: Call_7275 | B8: C0011 | C8: 128 | D8: R01 | E8: 44928 | F8: 31 | G8: 2.8 | H8: 2023 | I8: Monday | J8: More than 2 hours | K8: 3 | L8: Jan | M8: 1
A9: Call_7276 | B9: C0011 | C9: 49 | D9: R02 | E9: 44929 | F9: 135 | G9: 4.8 | H9: 2023 | I9: Tuesday | J9: 30 to 60 mins | K9: 5 | L9: Jan | M9: 1
A10: Call_7277 | B10: C0007 | C10: 84 | D10: R05 | E10: 44929 | F10: 60 | G10: 4.7 | H10: 2023 | I10: Tuesday | J10: 1 to 2 hours | K10: 5 | L10: Jan | M10: 1
A11: Call_7278 | B11: C0003 | C11: 103 | D11: R04 | E11: 44929 | F11: 148 | G11: 4.4 | H11: 2023 | I11: Tuesday | J11: 1 to 2 hours | K11: 4 | L11: Jan | M11: 1
A12: Call_7279 | B12: C0005 | C12: 31 | D12: R02 | E12: 44929 | F12: 135 | G12: 3.6 | H12: 2023 | I12: Tuesday | J12: 30 to 60 mins | K12: 4 | L12: Jan | M12: 1
A13: Call_7280 | B13: C0010 | C13: 44 | D13: R03 | E13: 44929 | F13: 105 | G13: 2.9 | H13: 2023 | I13: Tuesday | J13: 30 to 60 mins | K13: 3 | L13: Jan | M13: 1
A14: Call_7281 | B14: C0011 | C14: 102 | D14: R02 | E14: 44929 | F14: 69 | G14: 4.9 | H14: 2023 | I14: Tuesday | J14: 1 to 2 hours | K14: 5 | L14: Jan | M14: 1
A15: Call_7282 | B15: C0013 | C15: 135 | D15: R05 | E15: 44929 | F15: 46 | G15: 3.4 | H15: 2023 | I15: Tuesday | J15: More than 2 hours | K15: 3 | L15: Jan | M15: 1
... A1003: Call_8270 | B1003: C0009 | C1003: 114 | D1003: R01 | E1003: 45291 | F1003: 40 | G1003: 3.9 | H1003: 2024 | I1003: Sunday | J1003: 1 to 2 hours | K1003: 4 | L1003: Dec | M1003: 12

Sheet Sheet1
A1: Data returned for Call count, Columbus, Male (First 1000 rows).
A3: calls[Call number] | B3: calls[Customer ID] | C3: calls[Duration] | D3: calls[Representative] | E3: calls[Date of Call] | F3: calls[Purchase Amount] | G3: calls[Satisfaction Rating] | H3: calls[FY] | I3: calls[Day of week] | J3: calls[Duration Bucket] | K3: calls[Rating rounded] | L3: calls[Date of Call (Month)] | M3: calls[Date of Call (Month Index)]
A4: Call_7273 | B4: C0005 | C4: 68 | D4: R02 | E4: 44927 | F4: 66 | G4: 4.7 | H4: 2023 | I4: Sunday | J4: 1 to 2 hours | K4: 5 | L4: Jan | M4: 1
A5: Call_7279 | B5: C0005 | C5: 31 | D5: R02 | E5: 44929 | F5: 135 | G5: 3.6 | H5: 2023 | I5: Tuesday | J5: 30 to 60 mins | K5: 4 | L5: Jan | M5: 1
A6: Call_7290 | B6: C0006 | C6: 48 | D6: R05 | E6: 44932 | F6: 30 | G6: 4.4 | H6: 2023 | I6: Friday | J6: 30 to 60 mins | K6: 4 | L6: Jan | M6: 1
A7: Call_7304 | B7: C0006 | C7: 160 | D7: R02 | E7: 44940 | F7: 105 | G7: 5 | H7: 2023 | I7: Saturday | J7: More than 2 hours | K7: 5 | L7: Jan | M7: 1
A8: Call_7305 | B8: C0001 | C8: 105 | D8: R05 | E8: 44941 | F8: 125 | G8: 4.8 | H8: 2023 | I8: Sunday | J8: 1 to 2 hours | K8: 5 | L8: Jan | M8: 1
A9: Call_7315 | B9: C0001 | C9: 105 | D9: R01 | E9: 44944 | F9: 56 | G9: 3.6 | H9: 2023 | I9: Wednesday | J9: 1 to 2 hours | K9: 4 | L9: Jan | M9: 1
A10: Call_7335 | B10: C0001 | C10: 147 | D10: R04 | E10: 44951 | F10: 105 | G10: 4.4 | H10: 2023 | I10: Wednesday | J10: More than 2 hours | K10: 4 | L10: Jan | M10: 1
A11: Call_7339 | B11: C0005 | C11: 81 | D11: R01 | E11: 44953 | F11: 156 | G11: 2.6 | H11: 2023 | I11: Friday | J11: 1 to 2 hours | K11: 3 | L11: Jan | M11: 1
A12: Call_7340 | B12: C0006 | C12: 141 | D12: R03 | E12: 44953 | F12: 54 | G12: 0 | H12: 2023 | I12: Friday | J12: More than 2 hours | K12: 0 | L12: Jan | M12: 1
A13: Call_7341 | B13: C0006 | C13: 168 | D13: R03 | E13: 44954 | F13: 160 | G13: 3.9 | H13: 2023 | I13: Saturday | J13: More than 2 hours | K13: 4 | L13: Jan | M13: 1
A14: Call_7342 | B14: C0001 | C14: 101 | D14: R01 | E14: 44954 | F14: 80 | G14: 4.8 | H14: 2023 | I14: Saturday | J14: 1 to 2 hours | K14: 5 | L14: Jan | M14: 1
A15: Call_7345 | B15: C0005 | C15: 42 | D15: R01 | E15: 44956 | F15: 205 | G15: 3.6 | H15: 2023 | I15: Monday | J15: 30 to 60 mins | K15: 4 | L15: Jan | M15: 1
... A209: Call_8264 | B209: C0006 | C209: 95 | D209: R04 | E209: 45289 | F209: 50 | G209: 2.9 | H209: 2024 | I209: Friday | J209: 1 to 2 hours | K209: 3 | L209: Dec | M209: 12

Sheet Sheet2
A1: Data returned for Total Amount, Cleveland - C0007, R05 (First 1000 rows).
A3: calls[Call number] | B3: calls[Customer ID] | C3: calls[Duration] | D3: calls[Representative] | E3: calls[Date of Call] | F3: calls[Purchase Amount] | G3: calls[Satisfaction Rating] | H3: calls[FY] | I3: calls[Day of week] | J3: calls[Duration Bucket] | K3: calls[Rating rounded] | L3: calls[Date of Call (Month)] | M3: calls[Date of Call (Month Index)]
A4: Call_7277 | B4: C0007 | C4: 84 | D4: R05 | E4: 44929 | F4: 60 | G4: 4.7 | H4: 2023 | I4: Tuesday | J4: 1 to 2 hours | K4: 5 | L4: Jan | M4: 1
A5: Call_7392 | B5: C0007 | C5: 155 | D5: R05 | E5: 44975 | F5: 180 | G5: 2.2 | H5: 2023 | I5: Saturday | J5: More than 2 hours | K5: 2 | L5: Feb | M5: 2
A6: Call_7444 | B6: C0007 | C6: 131 | D6: R05 | E6: 44990 | F6: 140 | G6: 4.1 | H6: 2023 | I6: Sunday | J6: More than 2 hours | K6: 4 | L6: Mar | M6: 3
A7: Call_7447 | B7: C0007 | C7: 113 | D7: R05 | E7: 44990 | F7: 42 | G7: 4.2 | H7: 2023 | I7: Sunday | J7: 1 to 2 hours | K7: 4 | L7: Mar | M7: 3
A8: Call_7617 | B8: C0007 | C8: 25 | D8: R05 | E8: 45027 | F8: 75 | G8: 3.9 | H8: 2023 | I8: Tuesday | J8: 10 to 30 mins | K8: 4 | L8: Apr | M8: 4
A9: Call_7696 | B9: C0007 | C9: 101 | D9: R05 | E9: 45043 | F9: 225 | G9: 1.9 | H9: 2023 | I9: Thursday | J9: 1 to 2 hours | K9: 2 | L9: Apr | M9: 4
A10: Call_7786 | B10: C0007 | C10: 63 | D10: R05 | E10: 45076 | F10: 44 | G10: 3 | H10: 2023 | I10: Tuesday | J10: 1 to 2 hours | K10: 3 | L10: May | M10: 5
A11: Call_7845 | B11: C0007 | C11: 39 | D11: R05 | E11: 45103 | F11: 176 | G11: 4.3 | H11: 2023 | I11: Monday | J11: 30 to 60 mins | K11: 4 | L11: Jun | M11: 6
A12: Call_7921 | B12: C0007 | C12: 71 | D12: R05 | E12: 45140 | F12: 170 | G12: 3.5 | H12: 2024 | I12: Wednesday | J12: 1 to 2 hours | K12: 4 | L12: Aug | M12: 8
A13: Call_8016 | B13: C0007 | C13: 79 | D13: R05 | E13: 45192 | F13: 215 | G13: 4.6 | H13: 2024 | I13: Saturday | J13: 1 to 2 hours | K13: 5 | L13: Sep | M13: 9
A14: Call_8056 | B14: C0007 | C14: 142 | D14: R05 | E14: 45200 | F14: 44 | G14: 4.8 | H14: 2024 | I14: Sunday | J14: More than 2 hours | K14: 5 | L14: Oct | M14: 10
A15: Call_8114 | B15: C0007 | C15: 137 | D15: R05 | E15: 45216 | F15: 45 | G15: 4.4 | H15: 2024 | I15: Tuesday | J15: More than 2 hours | K15: 4 | L15: Oct | M15: 10

Sheet Sheet3
A3: Call count | B3: Total Amount | C3: Calls Duration | D3: Avg rate | E3: 5 star calls
A4: 1000 | B4: 96623 | C4: 89850 | D4: 3.8854 | E4: 307
A7: Call count | B7: Total Amount | C7: Calls Duration | D7: Avg rate | E7: 5 star calls
A8: 200 | B8: 20104 | C8: 18209 | D8: 3.8825 | E8: 51
A18: Row Labels | B18: Call count | C18: Call count2
A19: Jan | B19: 21 | C19: 21
A20: Feb | B20: 18 | C20: 18 | H20: Row Labels | I20: Call count
A21: Mar | B21: 31 | C21: 31 | H21: Sunday | I21: 27
A22: Apr | B22: 20 | C22: 20 | H22: Monday | I22: 22
A23: May | B23: 8 | C23: 8 | H23: Tuesday | I23: 27
A24: Jun | B24: 12 | C24: 12 | H24: Wednesday | I24: 27
A25: Jul | B25: 12 | C25: 12 | H25: Thursday | I25: 27
A26: Aug | B26: 7 | C26: 7 | H26: Friday | I26: 32
A27: Sep | B27: 20 | C27: 20 | H27: Saturday | I27: 38
A28: Oct | B28: 24 | C28: 24 | H28: Grand Total | I28: 200
A29: Nov | B29: 12 | C29: 12
A30: Dec | B30: 15 | C30: 15
A31: Grand Total | B31: 200 | C31: 200
H35: selected rep | I35: =F51 -> R05
B38: Row Labels | C38: Call count | D38: Total Amount | F38: rep | G38: calls | H38: amount | I38: Sel.cells | J38: sel.Amount
B39: R01 | C39: 189 | D39: 18415 | F39: =B39 -> R01 | G39: =C39 -> 189 | H39: =D39 -> 18415 | I39: =IF(F39=$I$35,G39,NA()) -> #N/A | J39: =IF(F39=$I$35,H39,NA()) -> #N/A
B40: R02 | C40: 218 | D40: 20581 | F40: =B40 -> R02 | G40: =C40 -> 218 | H40: =D40 -> 20581 | I40: =IF(F40=$I$35,G40,NA()) -> #N/A | J40: =IF(F40=$I$35,H40,NA()) -> #N/A
B41: R03 | C41: 207 | D41: 20872 | F41: =B41 -> R03 | G41: =C41 -> 207 | H41: =D41 -> 20872 | I41: =IF(F41=$I$35,G41,NA()) -> #N/A | J41: =IF(F41=$I$35,H41,NA()) -> #N/A
B42: R04 | C42: 186 | D42: 16651 | F42: =B42 -> R04 | G42: =C42 -> 186 | H42: =D42 -> 16651 | I42: =IF(F42=$I$35,G42,NA()) -> #N/A | J42: =IF(F42=$I$35,H42,NA()) -> #N/A
B43: R05 | C43: 200 | D43: 20104 | F43: =B43 -> R05 | G43: =C43 -> 200 | H43: =D43 -> 20104 | I43: =IF(F43=$I$35,G43,NA()) -> 200 | J43: =IF(F43=$I$35,H43,NA()) -> 20104
B44: Grand Total | C44: 1000 | D44: 96623
F50: Row Labels
F51: R05
A55: Call count | B55: Column Labels | J55: %calls | K55: =GETPIVOTDATA("[Measures].[Call count]",$A$7)/GETPIVOTDATA("[Measures].[Call count]",$A$3) -> 0.2
A56: Row Labels | B56: Female | C56: Male | D56: Grand Total | J56: calls | K56: =INDEX(G39:G43,MATCH(F51,F39:F43,0)) -> 200
A57: Cincinnati | B57: 144 | C57: 132 | D57: 276 | J57: amount | K57: =INDEX(H39:H43,MATCH(F51,F39:F43)) -> 20104
A58: Cleveland | B58: 326 | C58: 63 | D58: 389
A59: Columbus | B59: 129 | C59: 206 | D59: 335 | J59: call rank | K59: =_xlfn.RANK.AVG(K56,G39:G43) -> 3
A60: Grand Total | B60: 599 | C60: 401 | D60: 1000 | J60: amount rank | K60: =_xlfn.RANK.AVG(K57,H39:H43) -> 3
J63: Lables | K63: ="% of calls:"&TEXT(K55,"0%") -> % of calls:20%
K64: =IF(COUNTA(F51:F55)>1,"","Call Rank:"&K59) -> Call Rank:3
A65: Row Labels | B65: Call count | K65: =IF(COUNTA(F51:F55)>1,"","Amount Rank:"&K60) -> Amount Rank:3
A66: 2 | B66: 10 | J66: images: | K66: =INDEX( Assets!$F$3:$F$7,MATCH(F51,Assets!E3:E7)) -> 0
A67: 3 | B67: 44 | K67: =IF(COUNTA(F51:F55>1),"",K65)
A68: 4 | B68: 95
...

Sheet Dash Board
A1: Call Center Report Dynamic :
S19: Total Amount
S20: City Wise | T20: R01 | U20: R02 | V20: R03 | W20: R04 | X20: R05 | Y20: Total
S21: Cincinnati
S22: C0003 | T22: 891 | U22: 1332 | V22: 1282 | W22: 739 | X22: 560 | Y22: 4804
S23: C0004 | T23: 1991 | U23: 1886 | V23: 1206 | W23: 884 | X23: 1722 | Y23: 7689
S24: C0011 | T24: 1163 | U24: 1180 | V24: 1616 | W24: 1043 | X24: 1747 | Y24: 6749
S25: C0012 | T25: 1438 | U25: 1616 | V25: 866 | W25: 829 | X25: 2070 | Y25: 6819
S26: Cleveland
S27: C0002 | T27: 1233 | U27: 223 | V27: 1680 | W27: 990 | X27: 1508 | Y27: 5634
S28: C0007 | T28: 1598 | U28: 1907 | V28: 869 | W28: 1426 | X28: 1416 | Y28: 7216
S29: C0008 | T29: 900 | U29: 1016 | V29: 960 | W29: 940 | X29: 1193 | Y29: 5009
S30: C0010 | T30: 900 | U30: 1470 | V30: 1617 | W30: 1314 | X30: 941 | Y30: 6242
S31: C0013 | T31: 1255 | U31: 516 | V31: 1874 | W31: 1863 | X31: 1722 | Y31: 7230
S32: C0015 | T32: 1138 | U32: 1898 | V32: 1482 | W32: 846 | X32: 1154 | Y32: 6518 | Z32: =Sheet3!K63 -> % of calls:20%
S33: Columbus
S34: C0001 | T34: 1655 | U34: 805 | V34: 2263 | W34: 987 | X34: 1075 | Y34: 6785 | Z34: =Sheet3!K64 -> Call Rank:3
S35: C0005 | T35: 1104 | U35: 2280 | V35: 1445 | W35: 1722 | X35: 1196 | Y35: 7747
S36: C0006 | T36: 372 | U36: 1818 | V36: 1346 | W36: 1156 | X36: 1484 | Y36: 6176 | Z36: =Sheet3!K65 -> Amount Rank:3
S37: C0009 | T37: 1415 | U37: 1271 | V37: 1214 | W37: 1135 | X37: 1566 | Y37: 6601
S38: C0014 | T38: 1362 | U38: 1363 | V38: 1152 | W38: 777 | X38: 750 | Y38: 5404
